Traceback (most recent call last):
  File "/home/lv71161/cspiess/anaconda3/lib/python3.7/site-packages/tensorflow/python/pywrap_tensorflow.py", line 58, in <module>
    from tensorflow.python.pywrap_tensorflow_internal import *
  File "/home/lv71161/cspiess/anaconda3/lib/python3.7/site-packages/tensorflow/python/pywrap_tensorflow_internal.py", line 28, in <module>
    _pywrap_tensorflow_internal = swig_import_helper()
  File "/home/lv71161/cspiess/anaconda3/lib/python3.7/site-packages/tensorflow/python/pywrap_tensorflow_internal.py", line 24, in swig_import_helper
    _mod = imp.load_module('_pywrap_tensorflow_internal', fp, pathname, description)
  File "/home/lv71161/cspiess/anaconda3/lib/python3.7/imp.py", line 242, in load_module
    return load_dynamic(name, filename, file)
  File "/home/lv71161/cspiess/anaconda3/lib/python3.7/imp.py", line 342, in load_dynamic
    return _load(spec)
ImportError: /lib64/libstdc++.so.6: version `CXXABI_1.3.8' not found (required by /home/lv71161/cspiess/anaconda3/lib/python3.7/site-packages/tensorflow/python/_pywrap_tensorflow_internal.so)

During handling of the above exception, another exception occurred:

Traceback (most recent call last):
  File "code2seq.py", line 7, in <module>
    from model import Model
  File "/home/lv71161/cspiess/code2seq/model.py", line 8, in <module>
    import tensorflow as tf
  File "/home/lv71161/cspiess/anaconda3/lib/python3.7/site-packages/tensorflow/__init__.py", line 24, in <module>
    from tensorflow.python import pywrap_tensorflow  # pylint: disable=unused-import
  File "/home/lv71161/cspiess/anaconda3/lib/python3.7/site-packages/tensorflow/python/__init__.py", line 49, in <module>
    from tensorflow.python import pywrap_tensorflow
  File "/home/lv71161/cspiess/anaconda3/lib/python3.7/site-packages/tensorflow/python/pywrap_tensorflow.py", line 74, in <module>
    raise ImportError(msg)
ImportError: Traceback (most recent call last):
  File "/home/lv71161/cspiess/anaconda3/lib/python3.7/site-packages/tensorflow/python/pywrap_tensorflow.py", line 58, in <module>
    from tensorflow.python.pywrap_tensorflow_internal import *
  File "/home/lv71161/cspiess/anaconda3/lib/python3.7/site-packages/tensorflow/python/pywrap_tensorflow_internal.py", line 28, in <module>
    _pywrap_tensorflow_internal = swig_import_helper()
  File "/home/lv71161/cspiess/anaconda3/lib/python3.7/site-packages/tensorflow/python/pywrap_tensorflow_internal.py", line 24, in swig_import_helper
    _mod = imp.load_module('_pywrap_tensorflow_internal', fp, pathname, description)
  File "/home/lv71161/cspiess/anaconda3/lib/python3.7/imp.py", line 242, in load_module
    return load_dynamic(name, filename, file)
  File "/home/lv71161/cspiess/anaconda3/lib/python3.7/imp.py", line 342, in load_dynamic
    return _load(spec)
ImportError: /lib64/libstdc++.so.6: version `CXXABI_1.3.8' not found (required by /home/lv71161/cspiess/anaconda3/lib/python3.7/site-packages/tensorflow/python/_pywrap_tensorflow_internal.so)


Failed to load the native TensorFlow runtime.

See https://www.tensorflow.org/install/errors

for some common reasons and solutions.  Include the entire stack trace
above this error message when asking for help.
Traceback (most recent call last):
  File "/home/lv71161/cspiess/anaconda3/lib/python3.7/site-packages/tensorflow/python/pywrap_tensorflow.py", line 58, in <module>
    from tensorflow.python.pywrap_tensorflow_internal import *
  File "/home/lv71161/cspiess/anaconda3/lib/python3.7/site-packages/tensorflow/python/pywrap_tensorflow_internal.py", line 28, in <module>
    _pywrap_tensorflow_internal = swig_import_helper()
  File "/home/lv71161/cspiess/anaconda3/lib/python3.7/site-packages/tensorflow/python/pywrap_tensorflow_internal.py", line 24, in swig_import_helper
    _mod = imp.load_module('_pywrap_tensorflow_internal', fp, pathname, description)
  File "/home/lv71161/cspiess/anaconda3/lib/python3.7/imp.py", line 242, in load_module
    return load_dynamic(name, filename, file)
  File "/home/lv71161/cspiess/anaconda3/lib/python3.7/imp.py", line 342, in load_dynamic
    return _load(spec)
ImportError: /lib64/libstdc++.so.6: version `CXXABI_1.3.8' not found (required by /home/lv71161/cspiess/anaconda3/lib/python3.7/site-packages/tensorflow/python/_pywrap_tensorflow_internal.so)

During handling of the above exception, another exception occurred:

Traceback (most recent call last):
  File "code2seq.py", line 7, in <module>
    from model import Model
  File "/home/lv71161/cspiess/code2seq/model.py", line 8, in <module>
    import tensorflow as tf
  File "/home/lv71161/cspiess/anaconda3/lib/python3.7/site-packages/tensorflow/__init__.py", line 24, in <module>
    from tensorflow.python import pywrap_tensorflow  # pylint: disable=unused-import
  File "/home/lv71161/cspiess/anaconda3/lib/python3.7/site-packages/tensorflow/python/__init__.py", line 49, in <module>
    from tensorflow.python import pywrap_tensorflow
  File "/home/lv71161/cspiess/anaconda3/lib/python3.7/site-packages/tensorflow/python/pywrap_tensorflow.py", line 74, in <module>
    raise ImportError(msg)
ImportError: Traceback (most recent call last):
  File "/home/lv71161/cspiess/anaconda3/lib/python3.7/site-packages/tensorflow/python/pywrap_tensorflow.py", line 58, in <module>
    from tensorflow.python.pywrap_tensorflow_internal import *
  File "/home/lv71161/cspiess/anaconda3/lib/python3.7/site-packages/tensorflow/python/pywrap_tensorflow_internal.py", line 28, in <module>
    _pywrap_tensorflow_internal = swig_import_helper()
  File "/home/lv71161/cspiess/anaconda3/lib/python3.7/site-packages/tensorflow/python/pywrap_tensorflow_internal.py", line 24, in swig_import_helper
    _mod = imp.load_module('_pywrap_tensorflow_internal', fp, pathname, description)
  File "/home/lv71161/cspiess/anaconda3/lib/python3.7/imp.py", line 242, in load_module
    return load_dynamic(name, filename, file)
  File "/home/lv71161/cspiess/anaconda3/lib/python3.7/imp.py", line 342, in load_dynamic
    return _load(spec)
ImportError: /lib64/libstdc++.so.6: version `CXXABI_1.3.8' not found (required by /home/lv71161/cspiess/anaconda3/lib/python3.7/site-packages/tensorflow/python/_pywrap_tensorflow_internal.so)


Failed to load the native TensorFlow runtime.

See https://www.tensorflow.org/install/errors

for some common reasons and solutions.  Include the entire stack trace
above this error message when asking for help.
